Workbook

Sheet Start here
A1: Talum 1 (T11) — first cast: what to measure and record
A2: Version 2026-10-12 · R-D-alloys knowledge base · results go into knowledge/trials/T11.md §4
B4: Every value in this file calibrates the alloy models: solidification and Fe phases, recrystallisation and grain size, natural ageing, press force, can strength, surface oxide (MgO). Record what actually happened, not the targets.
B6: How to use
B7: 1. Plan — the checklist. Do all A rows; B if time allows. Set Status and Who.
B8: 2. Chemistry — one row per spectrometer sample. Out-of-spec T11 values turn red.
B9: 3. Process log — one column per coil (T11 and the reference alloy). Grey cells calculate themselves.
B10: 4. Results — one row per single reading. Pick the Plan ID; name and unit fill in.
B11: 5. Send the file back. The data go into the T11 record and the model calibration.
B13: Rules that make the data usable
B14: 1. Actual values with date and time. Slug age and can age are calculated from them.
B15: 2. Enter every single reading, not only the mean. The models need the scatter.
B16: 3. Same method for T11, REF and every repeat (same Brinell ball and load; conductivity at 20 °C or compensated).
B17: 4. Run the reference alloy (current production) through the same steps and tests in the same week.
... B38: Example Results rows (example values, not predictions)
B39: Date | C39: Sample ID | D39: Alloy | E39: Plan ID | F39: Position | G39: Variant | H39: Age (h) | I39: Value
B40: 2026-10-21 | C40: T11-C1-K1-SL-01 | D40: T11 | E40: SL01 | F40: full section | G40: air, furnace cool | H40: 4 | I40: 29.5
B41: 2026-10-22 | C41: T11-C1-K1-SL-01 | D41: T11 | E41: SL01 | F41: full section | G41: air, furnace cool | H41: 24 | I41: 30.1
B42: 2026-10-21 | C42: T11-C1-K1-SL-02 | D42: T11 | E42: SL02 | F42: centre | G42: air, furnace cool | I42: 64
B43: 2026-10-20 | C43: T11-C1-K1-LA-01 | D43: T11 | E43: SL01 | F43: full section | G43: lab 350 °C 1 h | I43: 41

Sheet Plan
A1: Measurement plan — Talum 1 (T11)
A2: Priority A = must, B = should. Ref = section or rule in the knowledge base.
A4: ID | B4: Stage | C4: What to measure | D4: Unit | E4: Method / instrument | F4: Where & when | G4: Samples | H4: Prio | I4: Model it feeds | J4: Why it matters | K4: Ref | L4: Record in | M4: Status | N4: Who
A5: G01 | B5: General | C5: Reference alloy: run the current production alloy through the same steps and tests in the same week | D5: – | E5: Same as T11 | F5: All stages, at least from the slug anneal on | G5: Same as T11 | H5: A | I5: Baseline | J5: Gives a direct T11 vs REF difference on the same furnace, press and day; removes line and day effects | K5: T11 §3 | L5: All sheets (Alloy = REF) | M5: open
A6: G02 | B6: General | C6: Event log: stops, strip breaks, temperature excursions, setting changes, with clock time | D6: text | E6: Operator log | F6: Whole trial | G6: – | H6: A | I6: All | J6: Lets the model explain or exclude outliers instead of learning noise | K6: – | L6: Process log (Events row) | M6: open
A7: G03 | B7: General | C7: Retained samples of every stage, labelled with Sample ID | D7: – | E7: Storage | F7: ≥ 1 m cast strip, ≥ 1 m hot band, ≥ 1 m as-rolled, 30 slugs and 30 cans per variant | G7: – | H7: A | I7: All | J7: Later tests (EBSD, XPS, extra ageing points) without a new cast | K7: – | L7: – | M7: open
A8: CH1 | B8: Chemistry | C8: Melt chemistry before and after correction | D8: wt % | E8: OES spark spectrometer | F8: Furnace, every sample | G8: All | H8: A | I8: Scrap blend | J8: Element recovery (Fe, Mn, Ti yield) and Mg burn-off for the scrap-mix model | K8: ch16 | L8: Chemistry | M8: open
A9: CH2 | B9: Chemistry | C9: Cast chemistry | D9: wt % | E9: OES spark spectrometer | F9: Cast start, middle, end | G9: 3 per cast | H9: A | I9: All models | J9: The actual composition is the model input, not the target | K9: T11 §1 | L9: Chemistry | M9: open
A10: CH3 | B10: Chemistry | C10: Through-thickness chemistry of the cast strip | D10: wt % | E10: OES on the strip surface and on strip milled to mid-thickness | F10: Mid-cast | G10: 1 + 1 | H10: B | I10: Solidification | J10: Centreline (Fe-rich) segregation on the rotary caster | K10: ch15; T11 §2.3 | L10: Chemistry | M10: open
A11: P1 | B11: Process | C11: Melt: charge weights, furnace and launder temperatures, hydrogen, grain-refiner feed and contact time | D11: various | E11: Charge sheet, thermocouple, hydrogen / density test | F11: Per cast | G11: – | H11: A | I11: Scrap blend; Solidification | J11: Refiner dose sets cast grain size and α vs β Fe phase; melt temperature sets superheat | K11: ch02 §3.8 | L11: Process log | M11: open
A12: P2 | B12: Process | C12: Caster: speed, strip thickness and width, cooling-water flow and temperatures, strip exit temperature, cracks | D12: various | E12: Caster log, pyrometer | F12: Continuous; note start, middle, end | G12: – | H12: A | I12: Solidification; Castability | J12: Speed and water set the cooling rate → cell size and Fe-phase type; cracks show the hot-tear limit | K12: ch15; ch01 §11 | L12: Process log | M12: open
A13: P3 | B13: Process | C13: Hot mill and bath: thickness in/out, temperatures in/out, speed, force, transfer times, bath and post-bath temperature | D13: various | E13: Mill log, pyrometer | F13: Per coil | G13: – | H13: A | I13: Hot flow; RX / grain size | J13: Force at known temperature and strain rate calibrates the hot flow law; the bath sets retained solute | K13: R24; ch19 §1.3 | L13: Process log | M13: open
A14: P4 | B14: Process | C14: Cold mill: thickness per pass, force, exit temperature; hot-band storage time | D14: various | E14: Mill log | F14: Per coil | G14: – | H14: A | I14: RX / grain size; Ageing | J14: Cold strain sets stored energy and the number of RX nuclei → grain size | K14: R14; ch19 P10 | L14: Process log | M14: open
A15: P5 | B15: Process | C15: Slug anneal: furnace, load, atmosphere, full temperature–time log from thermocouples in the slugs | D15: °C vs time | E15: Thermocouple logger, load centre and edge | F15: Every load | G15: – | H15: A | I15: RX / grain size; Ageing; Surface | J15: Heating rate shifts the RX temperature (up to ≈ 75 °C in Al–Mn); cooling rate decides Mg₂Si in solution vs precipitated | K15: ch03 §5.2; T11 §2.3 | L15: Process log + logger file | M15: open
A16: P6 | B16: Process | C16: Press: press and tool set, strokes/min, lubricant and amount, extrusion and bake dates | D16: text | E16: Press log | F16: Per lot | G16: – | H16: A | I16: Press force | J16: Context for force and reject data; dates give slug and can age | K16: ch10 | L16: Process log | M16: open
... A51: K08 | B51: Can | C51: Internal lacquer porosity / adhesion | D51: mA / grade | E51: Enamel rater; cross-cut test | F51: After the bake | G51: 10 cans | H51: B | I51: Surface (MgO) | J51: Oxide effect on the coating | K51: ch14 | L51: Results | M51: open

Sheet Chemistry
A1: Chemistry — every spectrometer sample (wt %)
A2: Enter ppm elements as wt % (5 ppm = 0.0005). Red = T11 sample outside the T11 window. Mn/Fe ≥ 0.5 favours compact α; Fe/Si > 1 avoids free Si, ≥ 2 avoids β.
A4: Sample ID | B4: Alloy | C4: Cast no. | D4: Sample point | E4: Date / time | F4: Si | G4: Fe | H4: Mn | I4: Mg | J4: Cu | K4: Ti | L4: Zn | M4: Cr | N4: Ni | O4: V | P4: Zr | Q4: B | R4: Ga | S4: Na | T4: Ca | U4: Pb | V4: Sn | W4: Mn/Fe | X4: Fe/Si | Y4: Mg/Si | Z4: Notes
A5: T11 target | F5: 0.38 | G5: 0.52 | H5: 0.14 | I5: 0.26 | J5: 0.038 | K5: 0.043 | L5: 0.034 | M5: 0.011 | W5: =IF(AND(ISNUMBER(H5),ISNUMBER(G5),N(G5)>0),H5/G5,"") | X5: =IF(AND(ISNUMBER(G5),ISNUMBER(F5),N(F5)>0),G5/F5,"") | Y5: =IF(AND(ISNUMBER(I5),ISNUMBER(F5),N(F5)>0),I5/F5,"")
A6: T11 min | F6: 0.37 | G6: 0.51 | H6: 0.13 | I6: 0.24
A7: T11 max | F7: 0.39 | G7: 0.53 | H7: 0.15 | I7: 0.28 | J7: 0.042 | K7: 0.05 | L7: 0.05 | M7: 0.03
A8: T11-C1-CH-FB | B8: T11 | C8: C1 | D8: Furnace before correction | W8: =IF(AND(ISNUMBER(H8),ISNUMBER(G8),N(G8)>0),H8/G8,"") | X8: =IF(AND(ISNUMBER(G8),ISNUMBER(F8),N(F8)>0),G8/F8,"") | Y8: =IF(AND(ISNUMBER(I8),ISNUMBER(F8),N(F8)>0),I8/F8,"")
A9: T11-C1-CH-FF | B9: T11 | C9: C1 | D9: Furnace final | W9: =IF(AND(ISNUMBER(H9),ISNUMBER(G9),N(G9)>0),H9/G9,"") | X9: =IF(AND(ISNUMBER(G9),ISNUMBER(F9),N(F9)>0),G9/F9,"") | Y9: =IF(AND(ISNUMBER(I9),ISNUMBER(F9),N(F9)>0),I9/F9,"")
A10: T11-C1-CH-CS | B10: T11 | C10: C1 | D10: Cast start | W10: =IF(AND(ISNUMBER(H10),ISNUMBER(G10),N(G10)>0),H10/G10,"") | X10: =IF(AND(ISNUMBER(G10),ISNUMBER(F10),N(F10)>0),G10/F10,"") | Y10: =IF(AND(ISNUMBER(I10),ISNUMBER(F10),N(F10)>0),I10/F10,"")
A11: T11-C1-CH-CM | B11: T11 | C11: C1 | D11: Cast middle | W11: =IF(AND(ISNUMBER(H11),ISNUMBER(G11),N(G11)>0),H11/G11,"") | X11: =IF(AND(ISNUMBER(G11),ISNUMBER(F11),N(F11)>0),G11/F11,"") | Y11: =IF(AND(ISNUMBER(I11),ISNUMBER(F11),N(F11)>0),I11/F11,"")
A12: T11-C1-CH-CE | B12: T11 | C12: C1 | D12: Cast end | W12: =IF(AND(ISNUMBER(H12),ISNUMBER(G12),N(G12)>0),H12/G12,"") | X12: =IF(AND(ISNUMBER(G12),ISNUMBER(F12),N(F12)>0),G12/F12,"") | Y12: =IF(AND(ISNUMBER(I12),ISNUMBER(F12),N(F12)>0),I12/F12,"")
A13: T11-C1-CH-SS | B13: T11 | C13: C1 | D13: Strip surface | W13: =IF(AND(ISNUMBER(H13),ISNUMBER(G13),N(G13)>0),H13/G13,"") | X13: =IF(AND(ISNUMBER(G13),ISNUMBER(F13),N(F13)>0),G13/F13,"") | Y13: =IF(AND(ISNUMBER(I13),ISNUMBER(F13),N(F13)>0),I13/F13,"")
A14: T11-C1-CH-SC | B14: T11 | C14: C1 | D14: Strip centre | W14: =IF(AND(ISNUMBER(H14),ISNUMBER(G14),N(G14)>0),H14/G14,"") | X14: =IF(AND(ISNUMBER(G14),ISNUMBER(F14),N(F14)>0),G14/F14,"") | Y14: =IF(AND(ISNUMBER(I14),ISNUMBER(F14),N(F14)>0),I14/F14,"")
A15: REF-C1-CH-CM | B15: REF | C15: C1 | D15: Cast middle | W15: =IF(AND(ISNUMBER(H15),ISNUMBER(G15),N(G15)>0),H15/G15,"") | X15: =IF(AND(ISNUMBER(G15),ISNUMBER(F15),N(F15)>0),G15/F15,"") | Y15: =IF(AND(ISNUMBER(I15),ISNUMBER(F15),N(F15)>0),I15/F15,"")
W16: =IF(AND(ISNUMBER(H16),ISNUMBER(G16),N(G16)>0),H16/G16,"") | X16: =IF(AND(ISNUMBER(G16),ISNUMBER(F16),N(F16)>0),G16/F16,"") | Y16: =IF(AND(ISNUMBER(I16),ISNUMBER(F16),N(F16)>0),I16/F16,"")
W17: =IF(AND(ISNUMBER(H17),ISNUMBER(G17),N(G17)>0),H17/G17,"") | X17: =IF(AND(ISNUMBER(G17),ISNUMBER(F17),N(F17)>0),G17/F17,"") | Y17: =IF(AND(ISNUMBER(I17),ISNUMBER(F17),N(F17)>0),I17/F17,"")
W18: =IF(AND(ISNUMBER(H18),ISNUMBER(G18),N(G18)>0),H18/G18,"") | X18: =IF(AND(ISNUMBER(G18),ISNUMBER(F18),N(F18)>0),G18/F18,"") | Y18: =IF(AND(ISNUMBER(I18),ISNUMBER(F18),N(F18)>0),I18/F18,"")
W19: =IF(AND(ISNUMBER(H19),ISNUMBER(G19),N(G19)>0),H19/G19,"") | X19: =IF(AND(ISNUMBER(G19),ISNUMBER(F19),N(F19)>0),G19/F19,"") | Y19: =IF(AND(ISNUMBER(I19),ISNUMBER(F19),N(F19)>0),I19/F19,"")
W20: =IF(AND(ISNUMBER(H20),ISNUMBER(G20),N(G20)>0),H20/G20,"") | X20: =IF(AND(ISNUMBER(G20),ISNUMBER(F20),N(F20)>0),G20/F20,"") | Y20: =IF(AND(ISNUMBER(I20),ISNUMBER(F20),N(F20)>0),I20/F20,"")
W21: =IF(AND(ISNUMBER(H21),ISNUMBER(G21),N(G21)>0),H21/G21,"") | X21: =IF(AND(ISNUMBER(G21),ISNUMBER(F21),N(F21)>0),G21/F21,"") | Y21: =IF(AND(ISNUMBER(I21),ISNUMBER(F21),N(F21)>0),I21/F21,"")
W22: =IF(AND(ISNUMBER(H22),ISNUMBER(G22),N(G22)>0),H22/G22,"") | X22: =IF(AND(ISNUMBER(G22),ISNUMBER(F22),N(F22)>0),G22/F22,"") | Y22: =IF(AND(ISNUMBER(I22),ISNUMBER(F22),N(F22)>0),I22/F22,"")
W23: =IF(AND(ISNUMBER(H23),ISNUMBER(G23),N(G23)>0),H23/G23,"") | X23: =IF(AND(ISNUMBER(G23),ISNUMBER(F23),N(F23)>0),G23/F23,"") | Y23: =IF(AND(ISNUMBER(I23),ISNUMBER(F23),N(F23)>0),I23/F23,"")
W24: =IF(AND(ISNUMBER(H24),ISNUMBER(G24),N(G24)>0),H24/G24,"") | X24: =IF(AND(ISNUMBER(G24),ISNUMBER(F24),N(F24)>0),G24/F24,"") | Y24: =IF(AND(ISNUMBER(I24),ISNUMBER(F24),N(F24)>0),I24/F24,"")
W25: =IF(AND(ISNUMBER(H25),ISNUMBER(G25),N(G25)>0),H25/G25,"") | X25: =IF(AND(ISNUMBER(G25),ISNUMBER(F25),N(F25)>0),G25/F25,"") | Y25: =IF(AND(ISNUMBER(I25),ISNUMBER(F25),N(F25)>0),I25/F25,"")
W26: =IF(AND(ISNUMBER(H26),ISNUMBER(G26),N(G26)>0),H26/G26,"") | X26: =IF(AND(ISNUMBER(G26),ISNUMBER(F26),N(F26)>0),G26/F26,"") | Y26: =IF(AND(ISNUMBER(I26),ISNUMBER(F26),N(F26)>0),I26/F26,"")
W27: =IF(AND(ISNUMBER(H27),ISNUMBER(G27),N(G27)>0),H27/G27,"") | X27: =IF(AND(ISNUMBER(G27),ISNUMBER(F27),N(F27)>0),G27/F27,"") | Y27: =IF(AND(ISNUMBER(I27),ISNUMBER(F27),N(F27)>0),I27/F27,"")
... W40: =IF(AND(ISNUMBER(H40),ISNUMBER(G40),N(G40)>0),H40/G40,"") | X40: =IF(AND(ISNUMBER(G40),ISNUMBER(F40),N(F40)>0),G40/F40,"") | Y40: =IF(AND(ISNUMBER(I40),ISNUMBER(F40),N(F40)>0),I40/F40,"")

Sheet Process log
A1: Process log — one column per coil
A2: Enter actual values. Grey cells calculate themselves. Melt rows: fill once per cast.
A4: Stage | B4: Parameter | C4: Unit | D4: Expected / target | E4: T11 coil 1 | F4: T11 coil 2 | G4: T11 coil 3 | H4: T11 coil 4 | I4: REF coil 1 | J4: REF coil 2 | K4: Notes
A5: ID | B5: Alloy | C5: – | D5: T11 / REF | E5: T11 | F5: T11 | G5: T11 | H5: T11 | I5: REF | J5: REF
A6: ID | B6: Cast no. | C6: –
A7: ID | B7: Coil no. | C7: – | E7: K1 | F7: K2 | G7: K3 | H7: K4 | I7: K1 | J7: K2
A8: ID | B8: Casting date and time | C8: date
A9: ID | B9: Trial variant | C9: text | D9: split; anneal atmosphere; cooling
A10: Melt | B10: T11S scrap charged | C10: kg | D10: ≈ 3,460 per 10 t (weigh-in)
A11: Melt | B11: 1xxx scrap charged | C11: kg | D11: ≈ 6,802 per 10 t
A12: Melt | B12: Primary or other Al charged | C12: kg
A13: Melt | B13: Al-75Fe | C13: kg | D13: ≈ 28 per 10 t
A14: Melt | B14: Al-20Mn | C14: kg | D14: ≈ 51 per 10 t
A15: Melt | B15: AlTi5B1 | C15: kg | D15: ≈ 10 per 10 t
A16: Melt | B16: Metal tapped | C16: kg
A17: Melt | B17: Furnace temperature at tapping | C17: °C
A18: Melt | B18: Launder / tundish temperature | C18: °C
A19: Melt | B19: Hydrogen or density index after degassing | C19: ml/100 g or %
A20: Melt | B20: Grain-refiner rod feed rate | C20: kg/t
A21: Melt | B21: Refiner contact time before the caster | C21: min
A22: Caster | B22: Casting speed | C22: m/min
A23: Caster | B23: Cast strip thickness | C23: mm | D23: 22
A24: Caster | B24: Strip width | C24: mm
A25: Caster | B25: Cooling-water flow | C25: m³/h
A26: Caster | B26: Cooling-water temperature in | C26: °C
A27: Caster | B27: Cooling-water temperature out | C27: °C
A28: Caster | B28: Strip temperature leaving the caster | C28: °C | D28: ≈ 500
A29: Caster | B29: Cracks / surface defects | C29: count per 100 m | D29: 0
A30: Hot mill | B30: Hot-band thickness | C30: mm | D30: ≤ 11 at ≥ 50 % reduction
A31: Hot mill | B31: Hot reduction | C31: % | D31: ≥ 50 % (current rule) | E31: =IF(AND(ISNUMBER(E23),ISNUMBER(E30),N(E23)>0),1-E30/E23,"") | F31: =IF(AND(ISNUMBER(F23),ISNUMBER(F30),N(F23)>0),1-F30/F23,"") | G31: =IF(AND(ISNUMBER(G23),ISNUMBER(G30),N(G23)>0),1-G30/G23,"") | H31: =IF(AND(ISNUMBER(H23),ISNUMBER(H30),N(H23)>0),1-H30/H23,"") | I31: =IF(AND(ISNUMBER(I23),ISNUMBER(I30),N(I23)>0),1-I30/I23,"") | J31: =IF(AND(ISNUMBER(J23),ISNUMBER(J30),N(J23)>0),1-J30/J23,"")
A32: Hot mill | B32: Hot true strain ε_hot | C32: – | E32: =IF(AND(ISNUMBER(E23),ISNUMBER(E30),N(E30)>0),LN(E23/E30),"") | F32: =IF(AND(ISNUMBER(F23),ISNUMBER(F30),N(F30)>0),LN(F23/F30),"") | G32: =IF(AND(ISNUMBER(G23),ISNUMBER(G30),N(G30)>0),LN(G23/G30),"") | H32: =IF(AND(ISNUMBER(H23),ISNUMBER(H30),N(H30)>0),LN(H23/H30),"") | I32: =IF(AND(ISNUMBER(I23),ISNUMBER(I30),N(I30)>0),LN(I23/I30),"") | J32: =IF(AND(ISNUMBER(J23),ISNUMBER(J30),N(J30)>0),LN(J23/J30),"")
A33: Hot mill | B33: Mill entry temperature | C33: °C | D33: ≈ 500
A34: Hot mill | B34: Mill exit temperature | C34: °C | D34: ≈ 380
A35: Hot mill | B35: Exit speed | C35: m/min
A36: Hot mill | B36: Rolling force | C36: kN
A37: Hot mill | B37: Time caster → mill | C37: s
A38: Hot mill | B38: Time mill → bath | C38: s
A39: Bath | B39: Bath water temperature | C39: °C
A40: Bath | B40: Strip temperature after the bath | C40: °C
A41: Bath | B41: Storage time before cold rolling | C41: h
...

Sheet Results
A1: Results — one row per single reading
A2: Pick the Plan ID; Measurement and Unit fill in. Age = hours after the anneal (slugs) or after the bake (cans).
A4: Date | B4: Sample ID | C4: Alloy | D4: Cast no. | E4: Coil no. | F4: Plan ID | G4: Measurement | H4: Unit | I4: Position | J4: Variant / condition | K4: Age (h) | L4: Value | M4: Method / instrument | N4: Operator | O4: Comment / photo file
G5: =IF(F5="","",IFERROR(INDEX(Plan!$C:$C,MATCH(F5,Plan!$A:$A,0)),"unknown ID")) | H5: =IF(F5="","",IFERROR(INDEX(Plan!$D:$D,MATCH(F5,Plan!$A:$A,0)),""))
G6: =IF(F6="","",IFERROR(INDEX(Plan!$C:$C,MATCH(F6,Plan!$A:$A,0)),"unknown ID")) | H6: =IF(F6="","",IFERROR(INDEX(Plan!$D:$D,MATCH(F6,Plan!$A:$A,0)),""))
G7: =IF(F7="","",IFERROR(INDEX(Plan!$C:$C,MATCH(F7,Plan!$A:$A,0)),"unknown ID")) | H7: =IF(F7="","",IFERROR(INDEX(Plan!$D:$D,MATCH(F7,Plan!$A:$A,0)),""))
G8: =IF(F8="","",IFERROR(INDEX(Plan!$C:$C,MATCH(F8,Plan!$A:$A,0)),"unknown ID")) | H8: =IF(F8="","",IFERROR(INDEX(Plan!$D:$D,MATCH(F8,Plan!$A:$A,0)),""))
G9: =IF(F9="","",IFERROR(INDEX(Plan!$C:$C,MATCH(F9,Plan!$A:$A,0)),"unknown ID")) | H9: =IF(F9="","",IFERROR(INDEX(Plan!$D:$D,MATCH(F9,Plan!$A:$A,0)),""))
G10: =IF(F10="","",IFERROR(INDEX(Plan!$C:$C,MATCH(F10,Plan!$A:$A,0)),"unknown ID")) | H10: =IF(F10="","",IFERROR(INDEX(Plan!$D:$D,MATCH(F10,Plan!$A:$A,0)),""))
G11: =IF(F11="","",IFERROR(INDEX(Plan!$C:$C,MATCH(F11,Plan!$A:$A,0)),"unknown ID")) | H11: =IF(F11="","",IFERROR(INDEX(Plan!$D:$D,MATCH(F11,Plan!$A:$A,0)),""))
G12: =IF(F12="","",IFERROR(INDEX(Plan!$C:$C,MATCH(F12,Plan!$A:$A,0)),"unknown ID")) | H12: =IF(F12="","",IFERROR(INDEX(Plan!$D:$D,MATCH(F12,Plan!$A:$A,0)),""))
G13: =IF(F13="","",IFERROR(INDEX(Plan!$C:$C,MATCH(F13,Plan!$A:$A,0)),"unknown ID")) | H13: =IF(F13="","",IFERROR(INDEX(Plan!$D:$D,MATCH(F13,Plan!$A:$A,0)),""))
G14: =IF(F14="","",IFERROR(INDEX(Plan!$C:$C,MATCH(F14,Plan!$A:$A,0)),"unknown ID")) | H14: =IF(F14="","",IFERROR(INDEX(Plan!$D:$D,MATCH(F14,Plan!$A:$A,0)),""))
G15: =IF(F15="","",IFERROR(INDEX(Plan!$C:$C,MATCH(F15,Plan!$A:$A,0)),"unknown ID")) | H15: =IF(F15="","",IFERROR(INDEX(Plan!$D:$D,MATCH(F15,Plan!$A:$A,0)),""))
G16: =IF(F16="","",IFERROR(INDEX(Plan!$C:$C,MATCH(F16,Plan!$A:$A,0)),"unknown ID")) | H16: =IF(F16="","",IFERROR(INDEX(Plan!$D:$D,MATCH(F16,Plan!$A:$A,0)),""))
... G404: =IF(F404="","",IFERROR(INDEX(Plan!$C:$C,MATCH(F404,Plan!$A:$A,0)),"unknown ID")) | H404: =IF(F404="","",IFERROR(INDEX(Plan!$D:$D,MATCH(F404,Plan!$A:$A,0)),""))

Sheet Lists
A1: Results Plan ID | B1: Position | D1: Chemistry sample point
A2: CS01 | B2: surface | D2: Furnace before correction
A3: CS02 | B3: quarter | D3: Furnace final
A4: CS03 | B4: centre | D4: Cast start
A5: CS04 | B5: edge | D5: Cast middle
A6: CS05 | B6: full section | D6: Cast end
A7: CS06 | B7: n/a | D7: Strip surface
A8: CS07 | D8: Strip centre
A9: HB01 | D9: Other
A10: HB02
A11: HB03
A12: CR01
A13: CR02
A14: CR03
A15: CR04
A16: SL01
A17: SL02
A18: SL03
A19: SL04
A20: SL05
A21: SL06
... A35: K08
